<?xml version="1.0" encoding="utf-8"?>
<!-- =================================================================================== -->
<!-- |    This document was autogenerated by xacro from robotiq_hande_world.urdf.xacro | -->
<!-- |    EDITING THIS FILE BY HAND IS NOT RECOMMENDED                                 | -->
<!-- =================================================================================== -->
<robot name="robotiq_hande">
  <joint name="hande_robotiq_hande_base_joint" type="fixed">
    <parent link="base_link"/>
    <child link="hande_robotiq_hande_base_link"/>
    <origin rpy="0 0 0" xyz="0 0 0"/>
  </joint>
  <link name="hande_robotiq_hande_base_link">
    <inertial>
      <origin rpy="1.57079632679 0 1.57079632679" xyz="0 0 0.04607"/>
      <mass value="0.86387"/>
      <inertia ixx="1017560E-9" ixy="0" ixz="2235E-9" iyy="1028041E-9" iyz="0" izz="489810E-9"/>
    </inertial>
    <visual>
      <origin rpy="1.57079632679 0 1.57079632679" xyz="0 0 0"/>
      <geometry>
        <mesh filename="package://robotiq_description/meshes/visual/hand-e.dae" scale="0.001 0.001 0.001"/>
      </geometry>
      <material name="Gazebo/Black">
        <color rgba="0.1 0.1 0.1 1"/>
      </material>
    </visual>
    <collision>
      <origin rpy="1.57079632679 0 1.57079632679" xyz="0 0 0"/>
      <geometry>
        <mesh filename="package://robotiq_description/meshes/collision/hand-e-collision.dae" scale="1 1 1"/>
      </geometry>
    </collision>
  </link>
  <gazebo reference="hande_robotiq_hande_base_link">
    <material>Gazebo/Black</material>
    <selfCollide>True</selfCollide>
  </gazebo>
  <link name="hande_robotiq_hande_left_finger">
    <inertial>
      <origin rpy="1.57079632679 0 1.57079632679" xyz="0.02262 -0.00759 0.00738"/>
      <mass value="0.03804"/>
      <inertia ixx="13567E-9" ixy="1849E-9" ixz="3622E-9" iyy="15784E-9" iyz="3616E-9" izz="7478E-9"/>
    </inertial>
    <visual>
      <origin rpy="1.57079632679 0 1.57079632679" xyz="0 0 0"/>
      <geometry>
        <mesh filename="package://robotiq_description/meshes/visual/hand-e_finger_1.dae" scale="0.001 0.001 0.001"/>
      </geometry>
      <material name="Gazebo/Grey">
        <color rgba="0.1 0.1 0.1 1"/>
      </material>
    </visual>
    <collision>
      <origin rpy="1.57079632679 0 1.57079632679" xyz="0 0 0"/>
      <geometry>
        <mesh filename="package://robotiq_description/meshes/collision/finger_1-collision.dae" scale="1 1 1"/>
      </geometry>
    </collision>
  </link>
  <gazebo reference="hande_robotiq_hande_left_finger">
    <material>Gazebo/Grey</material>
    <selfCollide>True</selfCollide>
  </gazebo>
  <link name="hande_robotiq_hande_right_finger">
    <inertial>
      <origin rpy="1.57079632679 0 1.57079632679" xyz="-0.02262 0.00759 0.00738"/>
      <mass value="0.03804"/>
      <inertia ixx="13567E-9" ixy="1849E-9" ixz="-3622E-9" iyy="15784E-9" iyz="-3616E-9" izz="7478E-9"/>
    </inertial>
    <visual>
      <origin rpy="1.57079632679 0 1.57079632679" xyz="0 0 0"/>
      <geometry>
        <mesh filename="package://robotiq_description/meshes/visual/hand-e_finger_2.dae" scale="0.001 0.001 0.001"/>
      </geometry>
      <material name="Gazebo/Grey">
        <color rgba="0.1 0.1 0.1 1"/>
      </material>
    </visual>
    <collision>
      <origin rpy="1.57079632679 0 1.57079632679" xyz="0 0 0"/>
      <geometry>
        <mesh filename="package://robotiq_description/meshes/collision/finger_2-collision.dae" scale="1 1 1"/>
      </geometry>
    </collision>
  </link>
  <gazebo reference="hande_robotiq_hande_right_finger">
    <material>Gazebo/Grey</material>
    <selfCollide>True</selfCollide>
  </gazebo>
  <joint name="hande_robotiq_hande_joint_finger" type="prismatic">
    <origin rpy="0 0 0" xyz="0.099 0 0"/>
    <parent link="hande_robotiq_hande_base_link"/>
    <child link="hande_robotiq_hande_left_finger"/>
    <axis xyz="0 -1 0"/>
    <limit effort="130" lower="0" upper="0.025" velocity="0.15"/>
  </joint>
  <joint name="hande_robotiq_hande_base_to_right_finger" type="prismatic">
    <origin rpy="0 0 0" xyz="0.099 0 0"/>
    <parent link="hande_robotiq_hande_base_link"/>
    <child link="hande_robotiq_hande_right_finger"/>
    <axis xyz="0 1 0"/>
    <limit effort="130" lower="0" upper="0.025" velocity="0.15"/>
    <mimic joint="hande_robotiq_hande_joint_finger" multiplier="1" offset="0"/>
  </joint>
  <transmission name="hande_robotiq_hande_joint_finger_trans">
    <type>transmission_interface/SimpleTransmission</type>
    <joint name="hande_robotiq_hande_joint_finger">
      <hardwareInterface>hardware_interface/PositionJointInterface</hardwareInterface>
    </joint>
    <actuator name="hande_robotiq_hande_joint_finger_motor">
      <mechanicalReduction>1</mechanicalReduction>
      <hardwareInterface>hardware_interface/PositionJointInterface</hardwareInterface>
    </actuator>
  </transmission>
  <gazebo>
    <plugin filename="libgazebo_mimic_joint_plugin.so" name="hande_mimic_robotiq_hande">
      <joint>hande_robotiq_hande_joint_finger</joint>
      <mimicJoint>hande_robotiq_hande_base_to_right_finger</mimicJoint>
    </plugin>
  </gazebo>
  <link name="base_link"/>
  <gazebo>
    <plugin filename="libgazebo_ros_joint_state_publisher.so" name="hande_joint_state">
      <ros>
        <argument>~/out:=hande_joint_states</argument>
      </ros>
      <update_rate>25</update_rate>
      <joint_name>hande_joint_finger</joint_name>
    </plugin>
  </gazebo>
</robot>

